[
    {
        "content": "<p>apepkuss opened <a href=\"https://github.com/bytecodealliance/wasmtime/issues/6212\">issue #6212</a>:</p>\n<blockquote>\n<p>I experimented with the async task cancellation when the given time's out. The following panic message is thrown:</p>\n<div class=\"codehilite\" data-code-language=\"Bash\"><pre><span></span><code>thread<span class=\"w\"> </span><span class=\"s1\">'tokio-runtime-worker'</span><span class=\"w\"> </span>panicked<span class=\"w\"> </span>at<span class=\"w\"> </span><span class=\"s1\">'fiber dropped without finishing'</span>,<span class=\"w\"> </span>/root/.cargo/registry/src/mirrors.tuna.tsinghua.edu.<span class=\"w\">  </span>cn-df7c3c540f42cdbd/wasmtime-fiber-6.0.1/src/lib.rs:164:9\n</code></pre></div>\n<p>By following the panic message, I found the <a href=\"https://github.com/bytecodealliance/wasmtime/blob/main/crates/fiber/src/lib.rs#L162-L166\">line 162-166</a> in <code>wasmedge-fiber</code> use <code>debug_assert!</code> to catch the yields during execution. Is there any more friendly way to deal with such cases? Thanks!</p>\n</blockquote>",
        "id": 349288227,
        "sender_full_name": "Wasmtime GitHub notifications bot",
        "timestamp": 1681457466
    },
    {
        "content": "<p>pchickey <a href=\"https://github.com/bytecodealliance/wasmtime/issues/6212#issuecomment-1508763181\">commented</a> on <a href=\"https://github.com/bytecodealliance/wasmtime/issues/6212\">issue #6212</a>:</p>\n<blockquote>\n<p>Thanks for the report. I need more information to reproduce this, can you make a small test case that shows the sort of cancellation that reaches this panic?</p>\n</blockquote>",
        "id": 349864974,
        "sender_full_name": "Wasmtime GitHub notifications bot",
        "timestamp": 1681485193
    }
]