[
    {
        "content": "<p>I have this weird bug in 17.0.3, I have a set a callback that yields until it reaches a max or final value. If this value is reached it returns a trap::interrupt error. Everything seems fine but as soon as a timeout each time I create a new sandbox and invoke a function on it, it seems like it tells me \"cannot enter component instance\" thought I would ask if anyone has seen anything similar?</p>",
        "id": 442513522,
        "sender_full_name": "Ashanti Mutinta",
        "timestamp": 1717502658
    },
    {
        "content": "<p>After a component instance traps it is no longer usable</p>",
        "id": 442519805,
        "sender_full_name": "Lann Martin",
        "timestamp": 1717504646
    },
    {
        "content": "<p>Even if it is a new sandbox? I guess I could just change the type of error returned</p>",
        "id": 442519973,
        "sender_full_name": "Ashanti Mutinta",
        "timestamp": 1717504690
    },
    {
        "content": "<p>Could you expand on what you mean by \"new sandbox\"? The key type here in wasmtime would be the <code>Instance</code></p>",
        "id": 442520395,
        "sender_full_name": "Lann Martin",
        "timestamp": 1717504833
    },
    {
        "content": "<p>Oh yes sorry about that. A new instance being built from a preinit-module</p>",
        "id": 442520615,
        "sender_full_name": "Ashanti Mutinta",
        "timestamp": 1717504911
    },
    {
        "content": "<p>That should be fine. The error you are seeing means that the component has been entered and not \"cleanly\" exited; trapping would be the most obvious reason for that in this case <span aria-label=\"shrug\" class=\"emoji emoji-1f937\" role=\"img\" title=\"shrug\">:shrug:</span></p>",
        "id": 442520961,
        "sender_full_name": "Lann Martin",
        "timestamp": 1717505016
    },
    {
        "content": "<p>Are you able to reproduce this issue on the latest wasmtime release?</p>",
        "id": 442521098,
        "sender_full_name": "Lann Martin",
        "timestamp": 1717505055
    },
    {
        "content": "<p>(I doubt this is a wasmtime bug, but if it is then upgrading would be the first step)</p>",
        "id": 442521198,
        "sender_full_name": "Lann Martin",
        "timestamp": 1717505097
    },
    {
        "content": "<p>I see, awesome. I will see if this goes away if I just use another error type. We are a bit gated to this version, but I think I will convince them to move. Need all these nice new features anyway.</p>",
        "id": 442521279,
        "sender_full_name": "Ashanti Mutinta",
        "timestamp": 1717505125
    },
    {
        "content": "<blockquote>\n<p>I have a set a callback that yields until it reaches a max or final value. If this value is reached it returns a trap::interrupt error.</p>\n</blockquote>\n<p>Another thought: are you sure this value is being reset for each instance? If it is tracked as part of the <code>Store&lt;T&gt;</code> data (<code>T</code>) and the <code>Store</code> is reused between instances that value wouldn't automatically be reset for a new instance</p>",
        "id": 442522300,
        "sender_full_name": "Lann Martin",
        "timestamp": 1717505406
    },
    {
        "content": "<p>I think I create a store for each new instance but I should investigate if there is any reuse happening somewhere</p>",
        "id": 442522893,
        "sender_full_name": "Ashanti Mutinta",
        "timestamp": 1717505606
    }
]